Workbook
Name Helper: Fees!#REF!

Sheet Fees
B1: 43466 | C1: =EDATE(B1,1) -> 43497 | D1: =EDATE(C1,1) -> 43525 | E1: =EDATE(D1,1) -> 43556 | F1: =EDATE(E1,1) -> 43586 | G1: =EDATE(F1,1) -> 43617 | H1: =EDATE(G1,1) -> 43647 | I1: =EDATE(H1,1) -> 43678 | J1: =EDATE(I1,1) -> 43709 | ... AK1: =EDATE(AJ1,1) -> 44531 | AL1: 44562 | AM1: 44593 | AN1: 44621 | AO1: 44652 | AP1: 44682 | AQ1: 44713 | AR1: 44743 | AS1: 44774 | AT1: 44805 | AU1: 44835 | AV1: 44866 | AW1: 44896 | AX1: 44927 | AY1: 44958 | AZ1: 44986 | BA1: 45017 | BB1: 45047 | BC1: 45078 | BD1: 45108 | BE1: 45139 | BF1: 45170 | BG1: 45200 | BH1: 45231 | BI1: 45261 | BJ1: 45292 | BK1: 45323 | BL1: 45352 | BM1: 45383 | BN1: 45413 | BO1: 45444 | BP1: 45474 | BQ1: 45505 | BR1: 45536 | BS1: 45566 | BT1: 45597 | BU1: 45627 | BV1: 45658 | BW1: 45689 | BX1: 45717 | BY1: 45748 | BZ1: 45778 | CA1: 45809 | CB1: 45839 | CC1: 45870 | CD1: 45901 | CE1: 45931 | CF1: 45962 | CG1: 45992
A2: KÁT and Premium financial instrument NAF_KÁT and Premium financial instrument_NAF | B2: 1.193879 | C2: 2.133274 | D2: 2.685427 | E2: 2.64731 | F2: 2.711507 | G2: 2.391507 | H2: 1.8947986 | I2: 1.710392 | J2: 2.0001569 | K2: 1.9364681 | L2: 2.195532 | M2: 2.4799719 | N2: 1.904241 | O2: 2.9090869 | P2: 3.4900787 | Q2: 5.186495 | R2: 5.2740385 | S2: 4.238427 | T2: 3.4735636 | U2: 3.4978944 | V2: 2.588234 | W2: 2.6730234 | X2: 1.730858 | Y2: 1.650718 | Z2: 1.4819833 | AA2: 2.3417466 | AB2: 3.0400826 | AC2: 2.768293 | AD2: 3.2279179 | AE2: 1.7038511 | AF2: 0.20005319 | AG2: 1.9438634e-12 | AH2: -1.684147e-15 | AI2: -1.5062755e-13 | AJ2: -5.7100065e-15 | AK2: -8.9196753e-15 | AL2: -19.05 | AM2: -3.3186443 | AN2: -8.1377479 | AO2: 0 | AP2: 0 | AQ2: 0 | AR2: 0 | AS2: 0 | AT2: 0 | AU2: 0 | AV2: 0 | AW2: 0 | AX2: 0 | AY2: 0.042855 | AZ2: 0 | BA2: 1.20585 | BB2: 3.376815 | BC2: 2.3663797 | BD2: 2.819592 | BE2: 2.1339232 | BF2: 2.0985992 | BG2: 0.47974516 | BH2: 0.63544067 | BI2: 0.76315941 | BJ2: 2.3309163 | BK2: 4.6129268 | BL2: 6.7621704 | BM2: 10.664771 | BN2: 10.098569 | BO2: 7.3332464 | BP2: 5.8858748 | BQ2: 5.3402994 | BR2: 4.9377031 | BS2: 4.3812116 | BT2: 2.467031 | BU2: 0.38061251 | BV2: 0 | BW2: 0.47 | BX2: 0.45 | BY2: 1.7 | BZ2: 2.07 | CA2: 2.01 | CB2: 0.75 | CC2: 0.71 | CD2: 0.66 | CE2: 0.28 | CF2: 0 | CG2: 0
A3: KÁT and Premium financial instrument NAF/MV_KÁT and Premium financial instrument_NAF/MV | B3: 1.193879 | C3: 2.133274 | D3: 2.685427 | E3: 2.64731 | F3: 2.711507 | G3: 2.391507 | H3: 1.8947986 | I3: 1.710392 | J3: 2.0001569 | K3: 1.9364681 | L3: 2.195532 | M3: 2.4799719 | N3: 1.904241 | O3: 2.9090869 | P3: 3.4900787 | Q3: 5.186495 | R3: 5.2740385 | S3: 4.238427 | T3: 3.4735636 | U3: 3.4978944 | V3: 2.588234 | W3: 2.6730234 | X3: 1.730858 | Y3: 1.650718 | Z3: 1.4819833 | AA3: 2.3417466 | AB3: 3.0400826 | AC3: 2.768293 | AD3: 3.2279179 | AE3: 1.7038511 | AF3: 0.20005319 | AG3: 1.9438634e-12 | AH3: -1.684147e-15 | AI3: -1.5062755e-13 | AJ3: -5.7100065e-15 | AK3: -8.9196753e-15 | AL3: -19.05 | AM3: -3.3186443 | AN3: -8.1377479 | AO3: 0 | AP3: 0 | AQ3: 0 | AR3: 0 | AS3: 0 | AT3: 0 | AU3: 0 | AV3: 0 | AW3: 0 | AX3: 0 | AY3: 0.042855 | AZ3: 0 | BA3: 1.20585 | BB3: 3.376815 | BC3: 2.3663797 | BD3: 2.819592 | BE3: 2.1339232 | BF3: 2.0985992 | BG3: 0.47974516 | BH3: 0.63544067 | BI3: 0.76315941 | BJ3: 2.3309163 | BK3: 4.6129268 | BL3: 6.7621704 | BM3: 10.664771 | BN3: 10.098569 | BO3: 7.3332464 | BP3: 5.8858748 | BQ3: 5.3402994 | BR3: 4.9377031 | BS3: 4.3812116 | BT3: 2.467031 | BU3: 0.38061251 | BV3: 0 | BW3: 0.47 | BX3: 0.45 | BY3: 1.7 | BZ3: 2.07 | CA3: 2.01 | CB3: 0.75 | CC3: 0.71 | CD3: 0.66 | CE3: 0.28 | CF3: 0 | CG3: 0
A4: KÁT and Premium financial instrument MV_KÁT and Premium financial instrument_MV | B4: 1.193879 | C4: 2.133274 | D4: 2.685427 | E4: 2.64731 | F4: 2.711507 | G4: 2.391507 | H4: 1.8947986 | I4: 1.710392 | J4: 2.0001569 | K4: 1.9364681 | L4: 2.195532 | M4: 2.4799719 | N4: 1.904241 | O4: 2.9090869 | P4: 3.4900787 | Q4: 5.186495 | R4: 5.2740385 | S4: 4.238427 | T4: 3.4735636 | U4: 3.4978944 | V4: 2.588234 | W4: 2.6730234 | X4: 1.730858 | Y4: 1.650718 | Z4: 1.4819833 | AA4: 2.3417466 | AB4: 3.0400826 | AC4: 2.768293 | AD4: 3.2279179 | AE4: 1.7038511 | AF4: 0.20005319 | AG4: 1.9438634e-12 | AH4: -1.684147e-15 | AI4: -1.5062755e-13 | AJ4: -5.7100065e-15 | AK4: -8.9196753e-15 | AL4: -19.05 | AM4: -3.3186443 | AN4: -8.1377479 | AO4: 0 | AP4: 0 | AQ4: 0 | AR4: 0 | AS4: 0 | AT4: 0 | AU4: 0 | AV4: 0 | AW4: 0 | AX4: 0 | AY4: 0.042855 | AZ4: 0 | BA4: 1.20585 | BB4: 3.376815 | BC4: 2.3663797 | BD4: 2.819592 | BE4: 2.1339232 | BF4: 2.0985992 | BG4: 0.47974516 | BH4: 0.63544067 | BI4: 0.76315941 | BJ4: 2.3309163 | BK4: 4.6129268 | BL4: 6.7621704 | BM4: 10.664771 | BN4: 10.098569 | BO4: 7.3332464 | BP4: 5.8858748 | BQ4: 5.3402994 | BR4: 4.9377031 | BS4: 4.3812116 | BT4: 2.467031 | BU4: 0.38061251 | BV4: 0 | BW4: 0.47 | BX4: 0.45 | BY4: 1.7 | BZ4: 2.07 | CA4: 2.01 | CB4: 0.75 | CC4: 0.71 | CD4: 0.66 | CE4: 0.28 | CF4: 0 | CG4: 0
A5: KÁT and Premium financial instrument MV/LV1_KÁT and Premium financial instrument_MV/LV1 | B5: 1.193879 | C5: 2.133274 | D5: 2.685427 | E5: 2.64731 | F5: 2.711507 | G5: 2.391507 | H5: 1.8947986 | I5: 1.710392 | J5: 2.0001569 | K5: 1.9364681 | L5: 2.195532 | M5: 2.4799719 | N5: 1.904241 | O5: 2.9090869 | P5: 3.4900787 | Q5: 5.186495 | R5: 5.2740385 | S5: 4.238427 | T5: 3.4735636 | U5: 3.4978944 | V5: 2.588234 | W5: 2.6730234 | X5: 1.730858 | Y5: 1.650718 | Z5: 1.4819833 | AA5: 2.3417466 | AB5: 3.0400826 | AC5: 2.768293 | AD5: 3.2279179 | AE5: 1.7038511 | AF5: 0.20005319 | AG5: 1.9438634e-12 | AH5: -1.684147e-15 | AI5: -1.5062755e-13 | AJ5: -5.7100065e-15 | AK5: -8.9196753e-15 | AL5: -19.05 | AM5: -3.3186443 | AN5: -8.1377479 | AO5: 0 | AP5: 0 | AQ5: 0 | AR5: 0 | AS5: 0 | AT5: 0 | AU5: 0 | AV5: 0 | AW5: 0 | AX5: 0 | AY5: 0.042855 | AZ5: 0 | BA5: 1.20585 | BB5: 3.376815 | BC5: 2.3663797 | BD5: 2.819592 | BE5: 2.1339232 | BF5: 2.0985992 | BG5: 0.47974516 | BH5: 0.63544067 | BI5: 0.76315941 | BJ5: 2.3309163 | BK5: 4.6129268 | BL5: 6.7621704 | BM5: 10.664771 | BN5: 10.098569 | BO5: 7.3332464 | BP5: 5.8858748 | BQ5: 5.3402994 | BR5: 4.9377031 | BS5: 4.3812116 | BT5: 2.467031 | BU5: 0.38061251 | BV5: 0 | BW5: 0.47 | BX5: 0.45 | BY5: 1.7 | BZ5: 2.07 | CA5: 2.01 | CB5: 0.75 | CC5: 0.71 | CD5: 0.66 | CE5: 0.28 | CF5: 0 | CG5: 0
A6: KÁT and Premium financial instrument MV/LV3_KÁT and Premium financial instrument_MV/LV3 | B6: 1.193879 | C6: 2.133274 | D6: 2.685427 | E6: 2.64731 | F6: 2.711507 | G6: 2.391507 | H6: 1.8947986 | I6: 1.710392 | J6: 2.0001569 | K6: 1.9364681 | L6: 2.195532 | M6: 2.4799719 | N6: 1.904241 | O6: 2.9090869 | P6: 3.4900787 | Q6: 5.186495 | R6: 5.2740385 | S6: 4.238427 | T6: 3.4735636 | U6: 3.4978944 | V6: 2.588234 | W6: 2.6730234 | X6: 1.730858 | Y6: 1.650718 | Z6: 1.4819833 | AA6: 2.3417466 | AB6: 3.0400826 | AC6: 2.768293 | AD6: 3.2279179 | AE6: 1.7038511 | AF6: 0.20005319 | AG6: 1.9438634e-12 | AH6: -1.684147e-15 | AI6: -1.5062755e-13 | AJ6: -5.7100065e-15 | AK6: -8.9196753e-15 | AL6: -19.05 | AM6: -3.3186443 | AN6: -8.1377479 | AO6: 0 | AP6: 0 | AQ6: 0 | AR6: 0 | AS6: 0 | AT6: 0 | AU6: 0 | AV6: 0 | AW6: 0 | AX6: 0 | AY6: 0.042855 | AZ6: 0 | BA6: 1.20585 | BB6: 3.376815 | BC6: 2.3663797 | BD6: 2.819592 | BE6: 2.1339232 | BF6: 2.0985992 | BG6: 0.47974516 | BH6: 0.63544067 | BI6: 0.76315941 | BJ6: 2.3309163 | BK6: 4.6129268 | BL6: 6.7621704 | BM6: 10.664771 | BN6: 10.098569 | BO6: 7.3332464 | BP6: 5.8858748 | BQ6: 5.3402994 | BR6: 4.9377031 | BS6: 4.3812116 | BT6: 2.467031 | BU6: 0.38061251 | BV6: 0 | BW6: 0.47 | BX6: 0.45 | BY6: 1.7 | BZ6: 2.07 | CA6: 2.01 | CB6: 0.75 | CC6: 0.71 | CD6: 0.66 | CE6: 0.28 | CF6: 0 | CG6: 0
A7: KÁT and Premium financial instrument LV1_KÁT and Premium financial instrument_LV1 | B7: 1.193879 | C7: 2.133274 | D7: 2.685427 | E7: 2.64731 | F7: 2.711507 | G7: 2.391507 | H7: 1.8947986 | I7: 1.710392 | J7: 2.0001569 | K7: 1.9364681 | L7: 2.195532 | M7: 2.4799719 | N7: 1.904241 | O7: 2.9090869 | P7: 3.4900787 | Q7: 5.186495 | R7: 5.2740385 | S7: 4.238427 | T7: 3.4735636 | U7: 3.4978944 | V7: 2.588234 | W7: 2.6730234 | X7: 1.730858 | Y7: 1.650718 | Z7: 1.4819833 | AA7: 2.3417466 | AB7: 3.0400826 | AC7: 2.768293 | AD7: 3.2279179 | AE7: 1.7038511 | AF7: 0.20005319 | AG7: 1.9438634e-12 | AH7: -1.684147e-15 | AI7: -1.5062755e-13 | AJ7: -5.7100065e-15 | AK7: -8.9196753e-15 | AL7: -19.05 | AM7: -3.3186443 | AN7: -8.1377479 | AO7: 0 | AP7: 0 | AQ7: 0 | AR7: 0 | AS7: 0 | AT7: 0 | AU7: 0 | AV7: 0 | AW7: 0 | AX7: 0 | AY7: 0.042855 | AZ7: 0 | BA7: 1.20585 | BB7: 3.376815 | BC7: 2.3663797 | BD7: 2.819592 | BE7: 2.1339232 | BF7: 2.0985992 | BG7: 0.47974516 | BH7: 0.63544067 | BI7: 0.76315941 | BJ7: 2.3309163 | BK7: 4.6129268 | BL7: 6.7621704 | BM7: 10.664771 | BN7: 10.098569 | BO7: 7.3332464 | BP7: 5.8858748 | BQ7: 5.3402994 | BR7: 4.9377031 | BS7: 4.3812116 | BT7: 2.467031 | BU7: 0.38061251 | BV7: 0 | BW7: 0.47 | BX7: 0.45 | BY7: 1.7 | BZ7: 2.07 | CA7: 2.01 | CB7: 0.75 | CC7: 0.71 | CD7: 0.66 | CE7: 0.28 | CF7: 0 | CG7: 0
A8: KÁT and Premium financial instrument LV2_KÁT and Premium financial instrument_LV2 | B8: 1.193879 | C8: 2.133274 | D8: 2.685427 | E8: 2.64731 | F8: 2.711507 | G8: 2.391507 | H8: 1.8947986 | I8: 1.710392 | J8: 2.0001569 | K8: 1.9364681 | L8: 2.195532 | M8: 2.4799719 | N8: 1.904241 | O8: 2.9090869 | P8: 3.4900787 | Q8: 5.186495 | R8: 5.2740385 | S8: 4.238427 | T8: 3.4735636 | U8: 3.4978944 | V8: 2.588234 | W8: 2.6730234 | X8: 1.730858 | Y8: 1.650718 | Z8: 1.4819833 | AA8: 2.3417466 | AB8: 3.0400826 | AC8: 2.768293 | AD8: 3.2279179 | AE8: 1.7038511 | AF8: 0.20005319 | AG8: 1.9438634e-12 | AH8: -1.684147e-15 | AI8: -1.5062755e-13 | AJ8: -5.7100065e-15 | AK8: -8.9196753e-15 | AL8: -19.05 | AM8: -3.3186443 | AN8: -8.1377479 | AO8: 0 | AP8: 0 | AQ8: 0 | AR8: 0 | AS8: 0 | AT8: 0 | AU8: 0 | AV8: 0 | AW8: 0 | AX8: 0 | AY8: 0.042855 | AZ8: 0 | BA8: 1.20585 | BB8: 3.376815 | BC8: 2.3663797 | BD8: 2.819592 | BE8: 2.1339232 | BF8: 2.0985992 | BG8: 0.47974516 | BH8: 0.63544067 | BI8: 0.76315941 | BJ8: 2.3309163 | BK8: 4.6129268 | BL8: 6.7621704 | BM8: 10.664771 | BN8: 10.098569 | BO8: 7.3332464 | BP8: 5.8858748 | BQ8: 5.3402994 | BR8: 4.9377031 | BS8: 4.3812116 | BT8: 2.467031 | BU8: 0.38061251 | BV8: 0 | BW8: 0.47 | BX8: 0.45 | BY8: 1.7 | BZ8: 2.07 | CA8: 2.01 | CB8: 0.75 | CC8: 0.71 | CD8: 0.66 | CE8: 0.28 | CF8: 0 | CG8: 0
A9: KÁT and Premium financial instrument LV3_KÁT and Premium financial instrument_LV3 | B9: 1.193879 | C9: 2.133274 | D9: 2.685427 | E9: 2.64731 | F9: 2.711507 | G9: 2.391507 | H9: 1.8947986 | I9: 1.710392 | J9: 2.0001569 | K9: 1.9364681 | L9: 2.195532 | M9: 2.4799719 | N9: 1.904241 | O9: 2.9090869 | P9: 3.4900787 | Q9: 5.186495 | R9: 5.2740385 | S9: 4.238427 | T9: 3.4735636 | U9: 3.4978944 | V9: 2.588234 | W9: 2.6730234 | X9: 1.730858 | Y9: 1.650718 | Z9: 1.4819833 | AA9: 2.3417466 | AB9: 3.0400826 | AC9: 2.768293 | AD9: 3.2279179 | AE9: 1.7038511 | AF9: 0.20005319 | AG9: 1.9438634e-12 | AH9: -1.684147e-15 | AI9: -1.5062755e-13 | AJ9: -5.7100065e-15 | AK9: -8.9196753e-15 | AL9: -19.05 | AM9: -3.3186443 | AN9: -8.1377479 | AO9: 0 | AP9: 0 | AQ9: 0 | AR9: 0 | AS9: 0 | AT9: 0 | AU9: 0 | AV9: 0 | AW9: 0 | AX9: 0 | AY9: 0.042855 | AZ9: 0 | BA9: 1.20585 | BB9: 3.376815 | BC9: 2.3663797 | BD9: 2.819592 | BE9: 2.1339232 | BF9: 2.0985992 | BG9: 0.47974516 | BH9: 0.63544067 | BI9: 0.76315941 | BJ9: 2.3309163 | BK9: 4.6129268 | BL9: 6.7621704 | BM9: 10.664771 | BN9: 10.098569 | BO9: 7.3332464 | BP9: 5.8858748 | BQ9: 5.3402994 | BR9: 4.9377031 | BS9: 4.3812116 | BT9: 2.467031 | BU9: 0.38061251 | BV9: 0 | BW9: 0.47 | BX9: 0.45 | BY9: 1.7 | BZ9: 2.07 | CA9: 2.01 | CB9: 0.75 | CC9: 0.71 | CD9: 0.66 | CE9: 0.28 | CF9: 0 | CG9: 0
A10: Distribution fixed fee NAF_Distribution fixed fee_NAF | B10: 210216 | C10: 210216 | D10: 210216 | E10: 210216 | F10: 210216 | G10: 210216 | H10: 210216 | I10: 210216 | J10: 210216 | K10: 210216 | L10: 210216 | M10: 210216 | N10: 213024 | O10: 213024 | P10: 213024 | Q10: 213024 | R10: 213024 | S10: 213024 | T10: 213024 | U10: 213024 | V10: 213024 | W10: 213024 | X10: 213024 | Y10: 213024 | Z10: 213024 | AA10: 213024 | AB10: 213024 | AC10: 300744 | AD10: 300744 | AE10: 300744 | AF10: 300744 | AG10: 300744 | AH10: 300744 | AI10: 300744 | AJ10: 300744 | AK10: 300744 | AL10: 300744 | AM10: 300744 | AN10: 300744 | AO10: 300744 | AP10: 300744 | AQ10: 300744 | AR10: 331920 | AS10: 331920 | AT10: 331920 | AU10: 331920 | AV10: 331920 | AW10: 331920 | AX10: 331920 | AY10: 331920 | AZ10: 331920 | BA10: 331920 | BB10: 331920 | BC10: 331920 | BD10: 331920 | BE10: 331920 | BF10: 331920 | BG10: 331920 | BH10: 331920 | BI10: 331920 | BJ10: 433176 | BK10: 433176 | BL10: 433176 | BM10: 433176 | BN10: 433176 | BO10: 433176 | BP10: 433176 | BQ10: 433176 | BR10: 433176 | BS10: 433176 | BT10: 433176 | BU10: 433176 | BV10: 433008 | BW10: 433008 | BX10: 433008 | BY10: 433008 | BZ10: 433008 | CA10: 433008 | CB10: 433008 | CC10: 433008 | CD10: 433008 | CE10: 433008 | CF10: 433008 | CG10: 433008
A11: Distribution fixed fee NAF/MV_Distribution fixed fee_NAF/MV | B11: 105108 | C11: 105108 | D11: 105108 | E11: 105108 | F11: 105108 | G11: 105108 | H11: 105108 | I11: 105108 | J11: 105108 | K11: 105108 | L11: 105108 | M11: 105108 | N11: 106512 | O11: 106512 | P11: 106512 | Q11: 106512 | R11: 106512 | S11: 106512 | T11: 106512 | U11: 106512 | V11: 106512 | W11: 106512 | X11: 106512 | Y11: 106512 | Z11: 106512 | AA11: 106512 | AB11: 106512 | AC11: 150372 | AD11: 150372 | AE11: 150372 | AF11: 150372 | AG11: 150372 | AH11: 150372 | AI11: 150372 | AJ11: 150372 | AK11: 150372 | AL11: 150372 | AM11: 150372 | AN11: 150372 | AO11: 150372 | AP11: 150372 | AQ11: 150372 | AR11: 165960 | AS11: 165960 | AT11: 165960 | AU11: 165960 | AV11: 165960 | AW11: 165960 | AX11: 165960 | AY11: 165960 | AZ11: 165960 | BA11: 165960 | BB11: 165960 | BC11: 165960 | BD11: 165960 | BE11: 165960 | BF11: 165960 | BG11: 165960 | BH11: 165960 | BI11: 165960 | BJ11: 216588 | BK11: 216588 | BL11: 216588 | BM11: 216588 | BN11: 216588 | BO11: 216588 | BP11: 216588 | BQ11: 216588 | BR11: 216588 | BS11: 216588 | BT11: 216588 | BU11: 216588 | BV11: 216504 | BW11: 216504 | BX11: 216504 | BY11: 216504 | BZ11: 216504 | CA11: 216504 | CB11: 216504 | CC11: 216504 | CD11: 216504 | CE11: 216504 | CF11: 216504 | CG11: 216504
A12: Distribution fixed fee MV_Distribution fixed fee_MV | B12: 105108 | C12: 105108 | D12: 105108 | E12: 105108 | F12: 105108 | G12: 105108 | H12: 105108 | I12: 105108 | J12: 105108 | K12: 105108 | L12: 105108 | M12: 105108 | N12: 106512 | O12: 106512 | P12: 106512 | Q12: 106512 | R12: 106512 | S12: 106512 | T12: 106512 | U12: 106512 | V12: 106512 | W12: 106512 | X12: 106512 | Y12: 106512 | Z12: 106512 | AA12: 106512 | AB12: 106512 | AC12: 150372 | AD12: 150372 | AE12: 150372 | AF12: 150372 | AG12: 150372 | AH12: 150372 | AI12: 150372 | AJ12: 150372 | AK12: 150372 | AL12: 150372 | AM12: 150372 | AN12: 150372 | AO12: 150372 | AP12: 150372 | AQ12: 150372 | AR12: 165960 | AS12: 165960 | AT12: 165960 | AU12: 165960 | AV12: 165960 | AW12: 165960 | AX12: 165960 | AY12: 165960 | AZ12: 165960 | BA12: 165960 | BB12: 165960 | BC12: 165960 | BD12: 165960 | BE12: 165960 | BF12: 165960 | BG12: 165960 | BH12: 165960 | BI12: 165960 | BJ12: 216588 | BK12: 216588 | BL12: 216588 | BM12: 216588 | BN12: 216588 | BO12: 216588 | BP12: 216588 | BQ12: 216588 | BR12: 216588 | BS12: 216588 | BT12: 216588 | BU12: 216588 | BV12: 216504 | BW12: 216504 | BX12: 216504 | BY12: 216504 | BZ12: 216504 | CA12: 216504 | CB12: 216504 | CC12: 216504 | CD12: 216504 | CE12: 216504 | CF12: 216504 | CG12: 216504
A13: Distribution fixed fee MV/LV1_Distribution fixed fee_MV/LV1 | B13: 3504 | C13: 3504 | D13: 3504 | E13: 3504 | F13: 3504 | G13: 3504 | H13: 3504 | I13: 3504 | J13: 3504 | K13: 3504 | L13: 3504 | M13: 3504 | N13: 3552 | O13: 3552 | P13: 3552 | Q13: 3552 | R13: 3552 | S13: 3552 | T13: 3552 | U13: 3552 | V13: 3552 | W13: 3552 | X13: 3552 | Y13: 3552 | Z13: 3552 | AA13: 3552 | AB13: 3552 | AC13: 5016 | AD13: 5016 | AE13: 5016 | AF13: 5016 | AG13: 5016 | AH13: 5016 | AI13: 5016 | AJ13: 5016 | AK13: 5016 | AL13: 5016 | AM13: 5016 | AN13: 5016 | AO13: 5016 | AP13: 5016 | AQ13: 5016 | AR13: 5532 | AS13: 5532 | AT13: 5532 | AU13: 5532 | AV13: 5532 | AW13: 5532 | AX13: 5532 | AY13: 5532 | AZ13: 5532 | BA13: 5532 | BB13: 5532 | BC13: 5532 | BD13: 5532 | BE13: 5532 | BF13: 5532 | BG13: 5532 | BH13: 5532 | BI13: 5532 | BJ13: 7224 | BK13: 7224 | BL13: 7224 | BM13: 7224 | BN13: 7224 | BO13: 7224 | BP13: 7224 | BQ13: 7224 | BR13: 7224 | BS13: 7224 | BT13: 7224 | BU13: 7224 | BV13: 7212 | BW13: 7212 | BX13: 7212 | BY13: 7212 | BZ13: 7212 | CA13: 7212 | CB13: 7212 | CC13: 7212 | CD13: 7212 | CE13: 7212 | CF13: 7212 | CG13: 7212
... A39: Distribution reactive energy fee LV1_Distribution reactive energy fee_LV1 | B39: 3.79 | C39: 3.79 | D39: 3.79 | E39: 3.79 | F39: 3.79 | G39: 3.79 | H39: 3.79 | I39: 3.79 | J39: 3.79 | K39: 3.79 | L39: 3.79 | M39: 3.79 | N39: 3.82 | O39: 3.82 | P39: 3.82 | Q39: 3.82 | R39: 3.82 | S39: 3.82 | T39: 3.82 | U39: 3.82 | V39: 3.82 | W39: 3.82 | X39: 3.82 | Y39: 3.82 | Z39: 3.82 | AA39: 3.82 | AB39: 3.82 | AC39: 4.21 | AD39: 4.21 | AE39: 4.21 | AF39: 4.21 | AG39: 4.21 | AH39: 4.21 | AI39: 4.21 | AJ39: 4.21 | AK39: 4.21 | AL39: 4.21 | AM39: 4.21 | AN39: 4.21 | AO39: 4.21 | AP39: 4.21 | AQ39: 4.21 | AR39: 4.21 | AS39: 4.21 | AT39: 4.21 | AU39: 4.21 | AV39: 4.21 | AW39: 4.21 | AX39: 4.21 | AY39: 4.21 | AZ39: 4.21 | BA39: 4.21 | BB39: 4.21 | BC39: 4.21 | BD39: 4.21 | BE39: 4.21 | BF39: 4.21 | BG39: 4.21 | BH39: 4.21 | BI39: 4.21 | BJ39: 4.21 | BK39: 4.21 | BL39: 4.21 | BM39: 4.21 | BN39: 4.21 | BO39: 4.21 | BP39: 4.21 | BQ39: 4.21 | BR39: 4.21 | BS39: 4.21 | BT39: 4.21 | BU39: 4.21 | BV39: 5.47 | BW39: 5.47 | BX39: 5.47 | BY39: 5.47 | BZ39: 5.47 | CA39: 5.47 | CB39: 5.47 | CC39: 5.47 | CD39: 5.47 | CE39: 5.47 | CF39: 5.47 | CG39: 5.47
A40: Distribution reactive energy fee LV2_Distribution reactive energy fee_LV2 | B40: - | C40: - | D40: - | E40: - | F40: - | G40: - | H40: - | I40: - | J40: - | K40: - | L40: - | M40: - | N40: 0 | O40: 0 | P40: 0 | Q40: 0 | R40: 0 | S40: 0 | T40: 0 | U40: 0 | V40: 0 | W40: 0 | X40: 0 | Y40: 0 | Z40: 0 | AA40: 0 | AB40: 0 | AC40: 0 | AD40: 0 | AE40: 0 | AF40: 0 | AG40: 0 | AH40: 0 | AI40: 0 | AJ40: 0 | AK40: 0 | AL40: 0 | AM40: 0 | AN40: 0 | AO40: 0 | AP40: 0 | AQ40: 0 | AR40: 0 | AS40: 0 | AT40: 0 | AU40: 0 | AV40: 0 | AW40: 0 | AX40: 0 | AY40: 0 | AZ40: 0 | BA40: 0 | BB40: 0 | BC40: 0 | BD40: 0 | BE40: 0 | BF40: 0 | BG40: 0 | BH40: 0 | BI40: 0 | BJ40: 0 | BK40: 0 | BL40: 0 | BM40: 0 | BN40: 0 | BO40: 0 | BP40: 0 | BQ40: 0 | BR40: 0 | BS40: 0 | BT40: 0 | BU40: 0 | BV40: 0 | BW40: 0 | BX40: 0 | BY40: 0 | BZ40: 0 | CA40: 0 | CB40: 0 | CC40: 0 | CD40: 0 | CE40: 0 | CF40: 0 | CG40: 0
A41: Distribution reactive energy fee LV3_Distribution reactive energy fee_LV3 | B41: 3.79 | C41: 4.79 | D41: 5.79 | E41: 6.79 | F41: 7.79 | G41: 8.79 | H41: 9.79 | I41: 10.79 | J41: 11.79 | K41: 12.79 | L41: 13.79 | M41: 14.79 | N41: 3.82 | O41: 3.82 | P41: 3.82 | Q41: 3.82 | R41: 3.82 | S41: 3.82 | T41: 3.82 | U41: 3.82 | V41: 3.82 | W41: 3.82 | X41: 3.82 | Y41: 3.82 | Z41: 3.82 | AA41: 3.82 | AB41: 3.82 | AC41: 4.21 | AD41: 4.21 | AE41: 4.21 | AF41: 4.21 | AG41: 4.21 | AH41: 4.21 | AI41: 4.21 | AJ41: 4.21 | AK41: 4.21 | AL41: 4.21 | AM41: 4.21 | AN41: 4.21 | AO41: 4.21 | AP41: 4.21 | AQ41: 4.21 | AR41: 5.12 | AS41: 5.12 | AT41: 5.12 | AU41: 5.12 | AV41: 5.12 | AW41: 5.12 | AX41: 5.12 | AY41: 5.12 | AZ41: 5.12 | BA41: 5.12 | BB41: 5.12 | BC41: 5.12 | BD41: 5.12 | BE41: 5.12 | BF41: 5.12 | BG41: 5.12 | BH41: 5.12 | BI41: 5.12 | BJ41: 4.85 | BK41: 4.85 | BL41: 4.85 | BM41: 4.85 | BN41: 4.85 | BO41: 4.85 | BP41: 4.85 | BQ41: 4.85 | BR41: 4.85 | BS41: 4.85 | BT41: 4.85 | BU41: 4.85 | BV41: 5.47 | BW41: 5.47 | BX41: 5.47 | BY41: 5.47 | BZ41: 5.47 | CA41: 5.47 | CB41: 5.47 | CC41: 5.47 | CD41: 5.47 | CE41: 5.47 | CF41: 5.47 | CG41: 5.47
A42: Distribution loss fee NAF_Distribution loss fee_NAF | B42: 0.19 | C42: 0.19 | D42: 0.19 | E42: 0.19 | F42: 0.19 | G42: 0.19 | H42: 0.19 | I42: 0.19 | J42: 0.19 | K42: 0.19 | L42: 0.19 | M42: 0.19 | N42: 0.22 | O42: 0.22 | P42: 0.22 | Q42: 0.22 | R42: 0.22 | S42: 0.22 | T42: 0.22 | U42: 0.22 | V42: 0.22 | W42: 0.22 | X42: 0.22 | Y42: 0.22 | Z42: 0.22 | AA42: 0.22 | AB42: 0.22 | AC42: 0 | AD42: 0 | AE42: 0 | AF42: 0 | AG42: 0 | AH42: 0 | AI42: 0 | AJ42: 0 | AK42: 0 | AL42: 0 | AM42: 0 | AN42: 0 | AO42: 0 | AP42: 0 | AQ42: 0 | AR42: 0 | AS42: 0 | AT42: 0 | AU42: 0 | AV42: 0 | AW42: 0 | AX42: 0 | AY42: 0 | AZ42: 0 | BA42: 0 | BB42: 0 | BC42: 0 | BD42: 0 | BE42: 0 | BF42: 0 | BG42: 0 | BH42: 0 | BI42: 0 | BJ42: 0 | BK42: 0 | BL42: 0 | BM42: 0 | BN42: 0 | BO42: 0 | BP42: 0 | BQ42: 0 | BR42: 0 | BS42: 0 | BT42: 0 | BU42: 0 | BV42: 0 | BW42: 0 | BX42: 0 | BY42: 0 | BZ42: 0 | CA42: 0 | CB42: 0 | CC42: 0 | CD42: 0 | CE42: 0 | CF42: 0 | CG42: 0
A43: Distribution loss fee NAF/MV_Distribution loss fee_NAF/MV | B43: 0.3 | C43: 0.3 | D43: 0.3 | E43: 0.3 | F43: 0.3 | G43: 0.3 | H43: 0.3 | I43: 0.3 | J43: 0.3 | K43: 0.3 | L43: 0.3 | M43: 0.3 | N43: 0.35 | O43: 0.35 | P43: 0.35 | Q43: 0.35 | R43: 0.35 | S43: 0.35 | T43: 0.35 | U43: 0.35 | V43: 0.35 | W43: 0.35 | X43: 0.35 | Y43: 0.35 | Z43: 0.35 | AA43: 0.35 | AB43: 0.35 | AC43: 0 | AD43: 0 | AE43: 0 | AF43: 0 | AG43: 0 | AH43: 0 | AI43: 0 | AJ43: 0 | AK43: 0 | AL43: 0 | AM43: 0 | AN43: 0 | AO43: 0 | AP43: 0 | AQ43: 0 | AR43: 0 | AS43: 0 | AT43: 0 | AU43: 0 | AV43: 0 | AW43: 0 | AX43: 0 | AY43: 0 | AZ43: 0 | BA43: 0 | BB43: 0 | BC43: 0 | BD43: 0 | BE43: 0 | BF43: 0 | BG43: 0 | BH43: 0 | BI43: 0 | BJ43: 0 | BK43: 0 | BL43: 0 | BM43: 0 | BN43: 0 | BO43: 0 | BP43: 0 | BQ43: 0 | BR43: 0 | BS43: 0 | BT43: 0 | BU43: 0 | BV43: 0 | BW43: 0 | BX43: 0 | BY43: 0 | BZ43: 0 | CA43: 0 | CB43: 0 | CC43: 0 | CD43: 0 | CE43: 0 | CF43: 0 | CG43: 0
A44: Distribution loss fee MV_Distribution loss fee_MV | B44: 1.02 | C44: 1.02 | D44: 1.02 | E44: 1.02 | F44: 1.02 | G44: 1.02 | H44: 1.02 | I44: 1.02 | J44: 1.02 | K44: 1.02 | L44: 1.02 | M44: 1.02 | N44: 1.19 | O44: 1.19 | P44: 1.19 | Q44: 1.19 | R44: 1.19 | S44: 1.19 | T44: 1.19 | U44: 1.19 | V44: 1.19 | W44: 1.19 | X44: 1.19 | Y44: 1.19 | Z44: 1.19 | AA44: 1.19 | AB44: 1.19 | AC44: 0 | AD44: 0 | AE44: 0 | AF44: 0 | AG44: 0 | AH44: 0 | AI44: 0 | AJ44: 0 | AK44: 0 | AL44: 0 | AM44: 0 | AN44: 0 | AO44: 0 | AP44: 0 | AQ44: 0 | AR44: 0 | AS44: 0 | AT44: 0 | AU44: 0 | AV44: 0 | AW44: 0 | AX44: 0 | AY44: 0 | AZ44: 0 | BA44: 0 | BB44: 0 | BC44: 0 | BD44: 0 | BE44: 0 | BF44: 0 | BG44: 0 | BH44: 0 | BI44: 0 | BJ44: 0 | BK44: 0 | BL44: 0 | BM44: 0 | BN44: 0 | BO44: 0 | BP44: 0 | BQ44: 0 | BR44: 0 | BS44: 0 | BT44: 0 | BU44: 0 | BV44: 0 | BW44: 0 | BX44: 0 | BY44: 0 | BZ44: 0 | CA44: 0 | CB44: 0 | CC44: 0 | CD44: 0 | CE44: 0 | CF44: 0 | CG44: 0
A45: Distribution loss fee MV/LV1_Distribution loss fee_MV/LV1 | B45: 1.95 | C45: 1.95 | D45: 1.95 | E45: 1.95 | F45: 1.95 | G45: 1.95 | H45: 1.95 | I45: 1.95 | J45: 1.95 | K45: 1.95 | L45: 1.95 | M45: 1.95 | N45: 2.28 | O45: 2.28 | P45: 2.28 | Q45: 2.28 | R45: 2.28 | S45: 2.28 | T45: 2.28 | U45: 2.28 | V45: 2.28 | W45: 2.28 | X45: 2.28 | Y45: 2.28 | Z45: 2.28 | AA45: 2.28 | AB45: 2.28 | AC45: 0 | AD45: 0 | AE45: 0 | AF45: 0 | AG45: 0 | AH45: 0 | AI45: 0 | AJ45: 0 | AK45: 0 | AL45: 0 | AM45: 0 | AN45: 0 | AO45: 0 | AP45: 0 | AQ45: 0 | AR45: 0 | AS45: 0 | AT45: 0 | AU45: 0 | AV45: 0 | AW45: 0 | AX45: 0 | AY45: 0 | AZ45: 0 | BA45: 0 | BB45: 0 | BC45: 0 | BD45: 0 | BE45: 0 | BF45: 0 | BG45: 0 | BH45: 0 | BI45: 0 | BJ45: 0 | BK45: 0 | BL45: 0 | BM45: 0 | BN45: 0 | BO45: 0 | BP45: 0 | BQ45: 0 | BR45: 0 | BS45: 0 | BT45: 0 | BU45: 0 | BV45: 0 | BW45: 0 | BX45: 0 | BY45: 0 | BZ45: 0 | CA45: 0 | CB45: 0 | CC45: 0 | CD45: 0 | CE45: 0 | CF45: 0 | CG45: 0
A46: Distribution loss fee MV/LV3_Distribution loss fee_MV/LV3 | B46: 1.95 | C46: 1.95 | D46: 1.95 | E46: 1.95 | F46: 1.95 | G46: 1.95 | H46: 1.95 | I46: 1.95 | J46: 1.95 | K46: 1.95 | L46: 1.95 | M46: 1.95 | N46: 2.28 | O46: 2.28 | P46: 2.28 | Q46: 2.28 | R46: 2.28 | S46: 2.28 | T46: 2.28 | U46: 2.28 | V46: 2.28 | W46: 2.28 | X46: 2.28 | Y46: 2.28 | Z46: 2.28 | AA46: 2.28 | AB46: 2.28 | AC46: 0 | AD46: 0 | AE46: 0 | AF46: 0 | AG46: 0 | AH46: 0 | AI46: 0 | AJ46: 0 | AK46: 0 | AL46: 0 | AM46: 0 | AN46: 0 | AO46: 0 | AP46: 0 | AQ46: 0 | AR46: 0 | AS46: 0 | AT46: 0 | AU46: 0 | AV46: 0 | AW46: 0 | AX46: 0 | AY46: 0 | AZ46: 0 | BA46: 0 | BB46: 0 | BC46: 0 | BD46: 0 | BE46: 0 | BF46: 0 | BG46: 0 | BH46: 0 | BI46: 0 | BJ46: 0 | BK46: 0 | BL46: 0 | BM46: 0 | BN46: 0 | BO46: 0 | BP46: 0 | BQ46: 0 | BR46: 0 | BS46: 0 | BT46: 0 | BU46: 0 | BV46: 0 | BW46: 0 | BX46: 0 | BY46: 0 | BZ46: 0 | CA46: 0 | CB46: 0 | CC46: 0 | CD46: 0 | CE46: 0 | CF46: 0 | CG46: 0
A47: Distribution loss fee LV1_Distribution loss fee_LV1 | B47: 3.03 | C47: 3.03 | D47: 3.03 | E47: 3.03 | F47: 3.03 | G47: 3.03 | H47: 3.03 | I47: 3.03 | J47: 3.03 | K47: 3.03 | L47: 3.03 | M47: 3.03 | N47: 3.54 | O47: 3.54 | P47: 3.54 | Q47: 3.54 | R47: 3.54 | S47: 3.54 | T47: 3.54 | U47: 3.54 | V47: 3.54 | W47: 3.54 | X47: 3.54 | Y47: 3.54 | Z47: 3.54 | AA47: 3.54 | AB47: 3.54 | AC47: 0 | AD47: 0 | AE47: 0 | AF47: 0 | AG47: 0 | AH47: 0 | AI47: 0 | AJ47: 0 | AK47: 0 | AL47: 0 | AM47: 0 | AN47: 0 | AO47: 0 | AP47: 0 | AQ47: 0 | AR47: 0 | AS47: 0 | AT47: 0 | AU47: 0 | AV47: 0 | AW47: 0 | AX47: 0 | AY47: 0 | AZ47: 0 | BA47: 0 | BB47: 0 | BC47: 0 | BD47: 0 | BE47: 0 | BF47: 0 | BG47: 0 | BH47: 0 | BI47: 0 | BJ47: 0 | BK47: 0 | BL47: 0 | BM47: 0 | BN47: 0 | BO47: 0 | BP47: 0 | BQ47: 0 | BR47: 0 | BS47: 0 | BT47: 0 | BU47: 0 | BV47: 0 | BW47: 0 | BX47: 0 | BY47: 0 | BZ47: 0 | CA47: 0 | CB47: 0 | CC47: 0 | CD47: 0 | CE47: 0 | CF47: 0 | CG47: 0
A48: Distribution loss fee LV2_Distribution loss fee_LV2 | B48: 2.26 | C48: 2.26 | D48: 2.26 | E48: 2.26 | F48: 2.26 | G48: 2.26 | H48: 2.26 | I48: 2.26 | J48: 2.26 | K48: 2.26 | L48: 2.26 | M48: 2.26 | N48: 2.64 | O48: 2.64 | P48: 2.64 | Q48: 2.64 | R48: 2.64 | S48: 2.64 | T48: 2.64 | U48: 2.64 | V48: 2.64 | W48: 2.64 | X48: 2.64 | Y48: 2.64 | Z48: 2.64 | AA48: 2.64 | AB48: 2.64 | AC48: 0 | AD48: 0 | AE48: 0 | AF48: 0 | AG48: 0 | AH48: 0 | AI48: 0 | AJ48: 0 | AK48: 0 | AL48: 0 | AM48: 0 | AN48: 0 | AO48: 0 | AP48: 0 | AQ48: 0 | AR48: 0 | AS48: 0 | AT48: 0 | AU48: 0 | AV48: 0 | AW48: 0 | AX48: 0 | AY48: 0 | AZ48: 0 | BA48: 0 | BB48: 0 | BC48: 0 | BD48: 0 | BE48: 0 | BF48: 0 | BG48: 0 | BH48: 0 | BI48: 0 | BJ48: 0 | BK48: 0 | BL48: 0 | BM48: 0 | BN48: 0 | BO48: 0 | BP48: 0 | BQ48: 0 | BR48: 0 | BS48: 0 | BT48: 0 | BU48: 0 | BV48: 0 | BW48: 0 | BX48: 0 | BY48: 0 | BZ48: 0 | CA48: 0 | CB48: 0 | CC48: 0 | CD48: 0 | CE48: 0 | CF48: 0 | CG48: 0
A49: Distribution loss fee LV3_Distribution loss fee_LV3 | B49: 3.03 | C49: 3.03 | D49: 3.03 | E49: 3.03 | F49: 3.03 | G49: 3.03 | H49: 3.03 | I49: 3.03 | J49: 3.03 | K49: 3.03 | L49: 3.03 | M49: 3.03 | N49: 3.54 | O49: 3.54 | P49: 3.54 | Q49: 3.54 | R49: 3.54 | S49: 3.54 | T49: 3.54 | U49: 3.54 | V49: 3.54 | W49: 3.54 | X49: 3.54 | Y49: 3.54 | Z49: 3.54 | AA49: 3.54 | AB49: 3.54 | AC49: 0 | AD49: 0 | AE49: 0 | AF49: 0 | AG49: 0 | AH49: 0 | AI49: 0 | AJ49: 0 | AK49: 0 | AL49: 0 | AM49: 0 | AN49: 0 | AO49: 0 | AP49: 0 | AQ49: 0 | AR49: 0 | AS49: 0 | AT49: 0 | AU49: 0 | AV49: 0 | AW49: 0 | AX49: 0 | AY49: 0 | AZ49: 0 | BA49: 0 | BB49: 0 | BC49: 0 | BD49: 0 | BE49: 0 | BF49: 0 | BG49: 0 | BH49: 0 | BI49: 0 | BJ49: 0 | BK49: 0 | BL49: 0 | BM49: 0 | BN49: 0 | BO49: 0 | BP49: 0 | BQ49: 0 | BR49: 0 | BS49: 0 | BT49: 0 | BU49: 0 | BV49: 0 | BW49: 0 | BX49: 0 | BY49: 0 | BZ49: 0 | CA49: 0 | CB49: 0 | CC49: 0 | CD49: 0 | CE49: 0 | CF49: 0 | CG49: 0
A50: Distribution balancing fee NAF_Distribution balancing fee_NAF | B50: 0 | C50: 0 | D50: 0 | E50: 0 | F50: 0 | G50: 0 | H50: 0 | I50: 0 | J50: 0 | K50: 0 | L50: 0 | M50: 0 | N50: 0 | O50: 0 | P50: 0 | Q50: 0 | R50: 0 | S50: 0 | T50: 0 | U50: 0 | V50: 0 | W50: 0 | X50: 0 | Y50: 0 | Z50: 0 | AA50: 0 | AB50: 0 | AC50: 0 | AD50: 0 | AE50: 0 | AF50: 0 | AG50: 0 | AH50: 0 | AI50: 0 | AJ50: 0 | AK50: 0 | AL50: 0 | AM50: 0 | AN50: 0 | AO50: 0 | AP50: 0 | AQ50: 0 | AR50: 0 | AS50: 0 | AT50: 0 | AU50: 0 | AV50: 0 | AW50: 0 | AX50: 0 | AY50: 0 | AZ50: 0 | BA50: 0 | BB50: 0 | BC50: 0 | BD50: 0 | BE50: 0 | BF50: 0 | BG50: 0 | BH50: 0 | BI50: 0 | BJ50: 0 | BK50: 0 | BL50: 0 | BM50: 0 | BN50: 0 | BO50: 0 | BP50: 0 | BQ50: 0 | BR50: 0 | BS50: 0 | BT50: 0 | BU50: 0 | BV50: 0 | BW50: 0 | BX50: 0 | BY50: 0 | BZ50: 0 | CA50: 0 | CB50: 0 | CC50: 0 | CD50: 0 | CE50: 0 | CF50: 0 | CG50: 0
A51: Distribution balancing fee NAF/MV_Distribution balancing fee_NAF/MV | B51: 0 | C51: 0 | D51: 0 | E51: 0 | F51: 0 | G51: 0 | H51: 0 | I51: 0 | J51: 0 | K51: 0 | L51: 0 | M51: 0 | N51: 0 | O51: 0 | P51: 0 | Q51: 0 | R51: 0 | S51: 0 | T51: 0 | U51: 0 | V51: 0 | W51: 0 | X51: 0 | Y51: 0 | Z51: 0 | AA51: 0 | AB51: 0 | AC51: 0 | AD51: 0 | AE51: 0 | AF51: 0 | AG51: 0 | AH51: 0 | AI51: 0 | AJ51: 0 | AK51: 0 | AL51: 0 | AM51: 0 | AN51: 0 | AO51: 0 | AP51: 0 | AQ51: 0 | AR51: 0 | AS51: 0 | AT51: 0 | AU51: 0 | AV51: 0 | AW51: 0 | AX51: 0 | AY51: 0 | AZ51: 0 | BA51: 0 | BB51: 0 | BC51: 0 | BD51: 0 | BE51: 0 | BF51: 0 | BG51: 0 | BH51: 0 | BI51: 0 | BJ51: 0 | BK51: 0 | BL51: 0 | BM51: 0 | BN51: 0 | BO51: 0 | BP51: 0 | BQ51: 0 | BR51: 0 | BS51: 0 | BT51: 0 | BU51: 0 | BV51: 0 | BW51: 0 | BX51: 0 | BY51: 0 | BZ51: 0 | CA51: 0 | CB51: 0 | CC51: 0 | CD51: 0 | CE51: 0 | CF51: 0 | CG51: 0
A52: Distribution balancing fee MV_Distribution balancing fee_MV | B52: 0 | C52: 0 | D52: 0 | E52: 0 | F52: 0 | G52: 0 | H52: 0 | I52: 0 | J52: 0 | K52: 0 | L52: 0 | M52: 0 | N52: 0 | O52: 0 | P52: 0 | Q52: 0 | R52: 0 | S52: 0 | T52: 0 | U52: 0 | V52: 0 | W52: 0 | X52: 0 | Y52: 0 | Z52: 0 | AA52: 0 | AB52: 0 | AC52: 0 | AD52: 0 | AE52: 0 | AF52: 0 | AG52: 0 | AH52: 0 | AI52: 0 | AJ52: 0 | AK52: 0 | AL52: 0 | AM52: 0 | AN52: 0 | AO52: 0 | AP52: 0 | AQ52: 0 | AR52: 0 | AS52: 0 | AT52: 0 | AU52: 0 | AV52: 0 | AW52: 0 | AX52: 0 | AY52: 0 | AZ52: 0 | BA52: 0 | BB52: 0 | BC52: 0 | BD52: 0 | BE52: 0 | BF52: 0 | BG52: 0 | BH52: 0 | BI52: 0 | BJ52: 0 | BK52: 0 | BL52: 0 | BM52: 0 | BN52: 0 | BO52: 0 | BP52: 0 | BQ52: 0 | BR52: 0 | BS52: 0 | BT52: 0 | BU52: 0 | BV52: 0 | BW52: 0 | BX52: 0 | BY52: 0 | BZ52: 0 | CA52: 0 | CB52: 0 | CC52: 0 | CD52: 0 | CE52: 0 | CF52: 0 | CG52: 0
... A99: Transmission fee above 132kV_Transmission fee_above 132kV | B99: 1.885 | C99: 1.885 | D99: 1.885 | E99: 1.885 | F99: 1.885 | G99: 1.885 | H99: 1.885 | I99: 1.885 | J99: 1.885 | K99: 1.885 | L99: 1.885 | M99: 1.885 | N99: 2.72 | O99: 2.72 | P99: 2.72 | Q99: 2.72 | R99: 2.72 | S99: 2.72 | T99: 2.72 | U99: 2.72 | V99: 2.72 | W99: 2.72 | X99: 2.72 | Y99: 2.72 | Z99: 2.72 | AA99: 2.72 | AB99: 2.72 | AC99: 3.012 | AD99: 3.012 | AE99: 3.012 | AF99: 3.012 | AG99: 3.012 | AH99: 3.012 | AI99: 3.012 | AJ99: 3.012 | AK99: 3.012 | AL99: 3.012 | AM99: 3.012 | AN99: 3.012 | AO99: 3.012 | AP99: 3.012 | AQ99: 3.012 | AR99: 10.42 | AS99: 10.42 | AT99: 10.42 | AU99: 10.42 | AV99: 10.42 | AW99: 10.42 | AX99: 10.42 | AY99: 10.42 | AZ99: 10.42 | BA99: 10.42 | BB99: 10.42 | BC99: 10.42 | BD99: 10.42 | BE99: 10.42 | BF99: 10.42 | BG99: 10.42 | BH99: 10.42 | BI99: 10.42 | BJ99: 6.8 | BK99: 6.8 | BL99: 6.8 | BM99: 6.8 | BN99: 6.8 | BO99: 6.8 | BP99: 6.8 | BQ99: 6.8 | BR99: 6.8 | BS99: 6.8 | BT99: 6.8 | BU99: 6.8 | BV99: 4.84 | BW99: 4.84 | BX99: 4.84 | BY99: 4.84 | BZ99: 4.84 | CA99: 4.84 | CB99: 4.84 | CC99: 4.84 | CD99: 4.84 | CE99: 4.84 | CF99: 4.84 | CG99: 4.84
BJ101: 1. A villamos energia rendszert vételezésre használó rendszerhasználó esetében,
BJ102: a) amennyiben az az átviteli hálózatra – közvetlenül vagy közvetve – 132 kV-nál nagyobb feszültségszinten csatlakozik 6,8 Ft/kWh | BV102: Az elosztók által 2025. január 1-től alkalmazható rendszerhasználati díjak
BJ103: b) amennyiben az az átviteli hálózatra – közvetlenül vagy közvetve – 132 kV-nál nem nagyobb feszültségszinten csatlakozik 8,68 Ft/kWh | BV103: Az elosztó hálózatra közvetlenül vagy közvetve csatlakozó rendszerhasználó esetében alkalmazandó átviteli forgalmi díj: 4,84 Ft/kWh
BJ104: 2. Az átviteli hálózatra csatlakozó elosztó esetében 6,8 Ft/kWh

Sheet Calculator
A1: Fee Name - Choose-- > | C1: t | D1: Month/Year | E1: Year | F1: Historical Fee (lookup) | G1: Include? | H1: Forecast Month/Year | I1: Forecast (calculated) | J1: Adjusted Final Forecasted Fee
A2: Distribution loss fee LV2_Distribution loss fee_LV2 | C2: 1 | D2: 43466 | E2: =YEAR(D2) -> 2019 | F2: =INDEX(Fees!$B$2:$CG$99, MATCH(Calculator!$A$2,Fees!$A$2:$A$99,0), MATCH(Calculator!D2,Fees!$B$1:$CG$1,0)) -> 2.26 | G2: =IF(AND(F2>0, ISNUMBER(C2)), "✅", "❌") -> ✅ | H2: 46023 | I2: {=IF(COUNT(F$2:F$1048576)=1, "", _xlfn.LET( _xlpm.HistDates, _xlfn._xlws.FILTER($D$2:$D$1000, ($F$2:$F$1000>0)), _xlpm.HistFees, _xlfn._xlws.FILTER($F$2:$F$1000, ($F$2:$F$1000>0)), IF(COUNTA(_xlpm.HistDates)<2, "", _xlfn.FORECAST.ETS(H2, _xlpm.HistFees, _xlpm.HistDates) ) ) )} -> 3.850989 | J2: =I2*(1+$A$4) -> 3.850989
A3: Manual Adjustment (%) | C3: 2 | D3: =EDATE(D2,1) -> 43497 | E3: =YEAR(D3) -> 2019 | F3: =INDEX(Fees!$B$2:$CG$99, MATCH(Calculator!$A$2,Fees!$A$2:$A$99,0), MATCH(Calculator!D3,Fees!$B$1:$CG$1,0)) -> 2.26 | G3: =IF(AND(F3>0, ISNUMBER(C3)), "✅", "❌") -> ✅ | H3: 46054 | I3: {=IF(COUNT(F$2:F$1048576)=1, "", _xlfn.LET( _xlpm.HistDates, _xlfn._xlws.FILTER($D$2:$D$1000, ($F$2:$F$1000>0)), _xlpm.HistFees, _xlfn._xlws.FILTER($F$2:$F$1000, ($F$2:$F$1000>0)), IF(COUNTA(_xlpm.HistDates)<2, "", _xlfn.FORECAST.ETS(H3, _xlpm.HistFees, _xlpm.HistDates) ) ) )} -> 3.8718681 | J3: =I3*(1+$A$4) -> 3.8718681
A4: 0 | C4: 3 | D4: =EDATE(D3,1) -> 43525 | E4: =YEAR(D4) -> 2019 | F4: =INDEX(Fees!$B$2:$CG$99, MATCH(Calculator!$A$2,Fees!$A$2:$A$99,0), MATCH(Calculator!D4,Fees!$B$1:$CG$1,0)) -> 2.26 | G4: =IF(AND(F4>0, ISNUMBER(C4)), "✅", "❌") -> ✅ | H4: 46082 | I4: {=IF(COUNT(F$2:F$1048576)=1, "", _xlfn.LET( _xlpm.HistDates, _xlfn._xlws.FILTER($D$2:$D$1000, ($F$2:$F$1000>0)), _xlpm.HistFees, _xlfn._xlws.FILTER($F$2:$F$1000, ($F$2:$F$1000>0)), IF(COUNTA(_xlpm.HistDates)<2, "", _xlfn.FORECAST.ETS(H4, _xlpm.HistFees, _xlpm.HistDates) ) ) )} -> 3.8927473 | J4: =I4*(1+$A$4) -> 3.8927473
C5: 4 | D5: =EDATE(D4,1) -> 43556 | E5: =YEAR(D5) -> 2019 | F5: =INDEX(Fees!$B$2:$CG$99, MATCH(Calculator!$A$2,Fees!$A$2:$A$99,0), MATCH(Calculator!D5,Fees!$B$1:$CG$1,0)) -> 2.26 | G5: =IF(AND(F5>0, ISNUMBER(C5)), "✅", "❌") -> ✅ | H5: 46113 | I5: {=IF(COUNT(F$2:F$1048576)=1, "", _xlfn.LET( _xlpm.HistDates, _xlfn._xlws.FILTER($D$2:$D$1000, ($F$2:$F$1000>0)), _xlpm.HistFees, _xlfn._xlws.FILTER($F$2:$F$1000, ($F$2:$F$1000>0)), IF(COUNTA(_xlpm.HistDates)<2, "", _xlfn.FORECAST.ETS(H5, _xlpm.HistFees, _xlpm.HistDates) ) ) )} -> 3.9136264 | J5: =I5*(1+$A$4) -> 3.9136264
C6: 5 | D6: =EDATE(D5,1) -> 43586 | E6: =YEAR(D6) -> 2019 | F6: =INDEX(Fees!$B$2:$CG$99, MATCH(Calculator!$A$2,Fees!$A$2:$A$99,0), MATCH(Calculator!D6,Fees!$B$1:$CG$1,0)) -> 2.26 | G6: =IF(AND(F6>0, ISNUMBER(C6)), "✅", "❌") -> ✅ | H6: 46143 | I6: {=IF(COUNT(F$2:F$1048576)=1, "", _xlfn.LET( _xlpm.HistDates, _xlfn._xlws.FILTER($D$2:$D$1000, ($F$2:$F$1000>0)), _xlpm.HistFees, _xlfn._xlws.FILTER($F$2:$F$1000, ($F$2:$F$1000>0)), IF(COUNTA(_xlpm.HistDates)<2, "", _xlfn.FORECAST.ETS(H6, _xlpm.HistFees, _xlpm.HistDates) ) ) )} -> 3.9345055 | J6: =I6*(1+$A$4) -> 3.9345055
A7: Average Fee of Previous Year 2025 | C7: 6 | D7: =EDATE(D6,1) -> 43617 | E7: =YEAR(D7) -> 2019 | F7: =INDEX(Fees!$B$2:$CG$99, MATCH(Calculator!$A$2,Fees!$A$2:$A$99,0), MATCH(Calculator!D7,Fees!$B$1:$CG$1,0)) -> 2.26 | G7: =IF(AND(F7>0, ISNUMBER(C7)), "✅", "❌") -> ✅ | H7: 46174 | I7: {=IF(COUNT(F$2:F$1048576)=1, "", _xlfn.LET( _xlpm.HistDates, _xlfn._xlws.FILTER($D$2:$D$1000, ($F$2:$F$1000>0)), _xlpm.HistFees, _xlfn._xlws.FILTER($F$2:$F$1000, ($F$2:$F$1000>0)), IF(COUNTA(_xlpm.HistDates)<2, "", _xlfn.FORECAST.ETS(H7, _xlpm.HistFees, _xlpm.HistDates) ) ) )} -> 3.9553846 | J7: =I7*(1+$A$4) -> 3.9553846
A8: =IFERROR(AVERAGEIF(F74:F85, ">0"),0) -> 0 | C8: 7 | D8: =EDATE(D7,1) -> 43647 | E8: =YEAR(D8) -> 2019 | F8: =INDEX(Fees!$B$2:$CG$99, MATCH(Calculator!$A$2,Fees!$A$2:$A$99,0), MATCH(Calculator!D8,Fees!$B$1:$CG$1,0)) -> 2.26 | G8: =IF(AND(F8>0, ISNUMBER(C8)), "✅", "❌") -> ✅ | H8: 46204 | I8: {=IF(COUNT(F$2:F$1048576)=1, "", _xlfn.LET( _xlpm.HistDates, _xlfn._xlws.FILTER($D$2:$D$1000, ($F$2:$F$1000>0)), _xlpm.HistFees, _xlfn._xlws.FILTER($F$2:$F$1000, ($F$2:$F$1000>0)), IF(COUNTA(_xlpm.HistDates)<2, "", _xlfn.FORECAST.ETS(H8, _xlpm.HistFees, _xlpm.HistDates) ) ) )} -> 3.9762637 | J8: =I8*(1+$A$4) -> 3.9762637
A9: Average Forecasted Fee | C9: 8 | D9: =EDATE(D8,1) -> 43678 | E9: =YEAR(D9) -> 2019 | F9: =INDEX(Fees!$B$2:$CG$99, MATCH(Calculator!$A$2,Fees!$A$2:$A$99,0), MATCH(Calculator!D9,Fees!$B$1:$CG$1,0)) -> 2.26 | G9: =IF(AND(F9>0, ISNUMBER(C9)), "✅", "❌") -> ✅ | H9: 46235 | I9: {=IF(COUNT(F$2:F$1048576)=1, "", _xlfn.LET( _xlpm.HistDates, _xlfn._xlws.FILTER($D$2:$D$1000, ($F$2:$F$1000>0)), _xlpm.HistFees, _xlfn._xlws.FILTER($F$2:$F$1000, ($F$2:$F$1000>0)), IF(COUNTA(_xlpm.HistDates)<2, "", _xlfn.FORECAST.ETS(H9, _xlpm.HistFees, _xlpm.HistDates) ) ) )} -> 3.9971429 | J9: =I9*(1+$A$4) -> 3.9971429
A10: =AVERAGE(J2:J13) -> 3.9658242 | C10: 9 | D10: =EDATE(D9,1) -> 43709 | E10: =YEAR(D10) -> 2019 | F10: =INDEX(Fees!$B$2:$CG$99, MATCH(Calculator!$A$2,Fees!$A$2:$A$99,0), MATCH(Calculator!D10,Fees!$B$1:$CG$1,0)) -> 2.26 | G10: =IF(AND(F10>0, ISNUMBER(C10)), "✅", "❌") -> ✅ | H10: 46266 | I10: {=IF(COUNT(F$2:F$1048576)=1, "", _xlfn.LET( _xlpm.HistDates, _xlfn._xlws.FILTER($D$2:$D$1000, ($F$2:$F$1000>0)), _xlpm.HistFees, _xlfn._xlws.FILTER($F$2:$F$1000, ($F$2:$F$1000>0)), IF(COUNTA(_xlpm.HistDates)<2, "", _xlfn.FORECAST.ETS(H10, _xlpm.HistFees, _xlpm.HistDates) ) ) )} -> 4.018022 | J10: =I10*(1+$A$4) -> 4.018022
A11: Projected Fee Based on YOY change | C11: 10 | D11: =EDATE(D10,1) -> 43739 | E11: =YEAR(D11) -> 2019 | F11: =INDEX(Fees!$B$2:$CG$99, MATCH(Calculator!$A$2,Fees!$A$2:$A$99,0), MATCH(Calculator!D11,Fees!$B$1:$CG$1,0)) -> 2.26 | G11: =IF(AND(F11>0, ISNUMBER(C11)), "✅", "❌") -> ✅ | H11: 46296 | I11: {=IF(COUNT(F$2:F$1048576)=1, "", _xlfn.LET( _xlpm.HistDates, _xlfn._xlws.FILTER($D$2:$D$1000, ($F$2:$F$1000>0)), _xlpm.HistFees, _xlfn._xlws.FILTER($F$2:$F$1000, ($F$2:$F$1000>0)), IF(COUNTA(_xlpm.HistDates)<2, "", _xlfn.FORECAST.ETS(H11, _xlpm.HistFees, _xlpm.HistDates) ) ) )} -> 4.0389011 | J11: =I11*(1+$A$4) -> 4.0389011
A12: =IF(A4>0, I25+(I25*J25) + A4*(I25+(I25*J25)),I25+(I25*J25)) -> 2.7246313 | C12: 11 | D12: =EDATE(D11,1) -> 43770 | E12: =YEAR(D12) -> 2019 | F12: =INDEX(Fees!$B$2:$CG$99, MATCH(Calculator!$A$2,Fees!$A$2:$A$99,0), MATCH(Calculator!D12,Fees!$B$1:$CG$1,0)) -> 2.26 | G12: =IF(AND(F12>0, ISNUMBER(C12)), "✅", "❌") -> ✅ | H12: 46327 | I12: {=IF(COUNT(F$2:F$1048576)=1, "", _xlfn.LET( _xlpm.HistDates, _xlfn._xlws.FILTER($D$2:$D$1000, ($F$2:$F$1000>0)), _xlpm.HistFees, _xlfn._xlws.FILTER($F$2:$F$1000, ($F$2:$F$1000>0)), IF(COUNTA(_xlpm.HistDates)<2, "", _xlfn.FORECAST.ETS(H12, _xlpm.HistFees, _xlpm.HistDates) ) ) )} -> 4.0597802 | J12: =I12*(1+$A$4) -> 4.0597802
A13: Weighted 3-year Rolling Average | C13: 12 | D13: =EDATE(D12,1) -> 43800 | E13: =YEAR(D13) -> 2019 | F13: =INDEX(Fees!$B$2:$CG$99, MATCH(Calculator!$A$2,Fees!$A$2:$A$99,0), MATCH(Calculator!D13,Fees!$B$1:$CG$1,0)) -> 2.26 | G13: =IF(AND(F13>0, ISNUMBER(C13)), "✅", "❌") -> ✅ | H13: 46357 | I13: {=IF(COUNT(F$2:F$1048576)=1, "", _xlfn.LET( _xlpm.HistDates, _xlfn._xlws.FILTER($D$2:$D$1000, ($F$2:$F$1000>0)), _xlpm.HistFees, _xlfn._xlws.FILTER($F$2:$F$1000, ($F$2:$F$1000>0)), IF(COUNTA(_xlpm.HistDates)<2, "", _xlfn.FORECAST.ETS(H13, _xlpm.HistFees, _xlpm.HistDates) ) ) )} -> 4.0806593 | J13: =I13*(1+$A$4) -> 4.0806593
A14: =IF(A4>0, AVERAGEIF(J31:J35, ">0") + (A4 * AVERAGEIF(J31:J35, ">0")), AVERAGEIF(J31:J35, ">0")) -> 2.5133333 | C14: 13 | D14: =EDATE(D13,1) -> 43831 | E14: =YEAR(D14) -> 2020 | F14: =INDEX(Fees!$B$2:$CG$99, MATCH(Calculator!$A$2,Fees!$A$2:$A$99,0), MATCH(Calculator!D14,Fees!$B$1:$CG$1,0)) -> 2.64 | G14: =IF(AND(F14>0, ISNUMBER(C14)), "✅", "❌") -> ✅
A15: Linear Trend (Regression) | C15: 14 | D15: =EDATE(D14,1) -> 43862 | E15: =YEAR(D15) -> 2020 | F15: =INDEX(Fees!$B$2:$CG$99, MATCH(Calculator!$A$2,Fees!$A$2:$A$99,0), MATCH(Calculator!D15,Fees!$B$1:$CG$1,0)) -> 2.64 | G15: =IF(AND(F15>0, ISNUMBER(C15)), "✅", "❌") -> ✅ | H15: Simple Year-over-Year (YoY) Growth Rate Projection
A16: Slope | B16: Intercept | C16: 15 | D16: =EDATE(D15,1) -> 43891 | E16: =YEAR(D16) -> 2020 | F16: =INDEX(Fees!$B$2:$CG$99, MATCH(Calculator!$A$2,Fees!$A$2:$A$99,0), MATCH(Calculator!D16,Fees!$B$1:$CG$1,0)) -> 2.64 | G16: =IF(AND(F16>0, ISNUMBER(C16)), "✅", "❌") -> ✅ | H16: average year-over-year percentage change
A17: {=LINEST(C2:C85,F2:F85)} -> -16.54832 | B17: 55.644094 | C17: 16 | D17: =EDATE(D16,1) -> 43922 | E17: =YEAR(D17) -> 2020 | F17: =INDEX(Fees!$B$2:$CG$99, MATCH(Calculator!$A$2,Fees!$A$2:$A$99,0), MATCH(Calculator!D17,Fees!$B$1:$CG$1,0)) -> 2.64 | G17: =IF(AND(F17>0, ISNUMBER(C17)), "✅", "❌") -> ✅ | H17: Year | I17: Average | J17: YoY Average Growth Rate
A18: Difference between Forecasted and Average fee of previous year | B18: =1-(A8/A10) -> 1 | C18: 17 | D18: =EDATE(D17,1) -> 43952 | E18: =YEAR(D18) -> 2020 | F18: =INDEX(Fees!$B$2:$CG$99, MATCH(Calculator!$A$2,Fees!$A$2:$A$99,0), MATCH(Calculator!D18,Fees!$B$1:$CG$1,0)) -> 2.64 | G18: =IF(AND(F18>0, ISNUMBER(C18)), "✅", "❌") -> ✅ | H18: 2019 | I18: =IF(COUNTIFS($E$2:$E$1000,H18,$F$2:$F$1000,">0")=0,"",AVERAGEIFS($F$2:$F$1000,$E$2:$E$1000,H18,$F$2:$F$1000,">0")) -> 2.26
C19: 18 | D19: =EDATE(D18,1) -> 43983 | E19: =YEAR(D19) -> 2020 | F19: =INDEX(Fees!$B$2:$CG$99, MATCH(Calculator!$A$2,Fees!$A$2:$A$99,0), MATCH(Calculator!D19,Fees!$B$1:$CG$1,0)) -> 2.64 | G19: =IF(AND(F19>0, ISNUMBER(C19)), "✅", "❌") -> ✅ | H19: 2020 | I19: =IF(COUNTIFS($E$2:$E$1000,H19,$F$2:$F$1000,">0")=0,"",AVERAGEIFS($F$2:$F$1000,$E$2:$E$1000,H19,$F$2:$F$1000,">0")) -> 2.64 | J19: =(I19-I18)/I18 -> 0.16814159
A20: Advice: Choose the higher end value where applicable! | C20: 19 | D20: =EDATE(D19,1) -> 44013 | E20: =YEAR(D20) -> 2020 | F20: =INDEX(Fees!$B$2:$CG$99, MATCH(Calculator!$A$2,Fees!$A$2:$A$99,0), MATCH(Calculator!D20,Fees!$B$1:$CG$1,0)) -> 2.64 | G20: =IF(AND(F20>0, ISNUMBER(C20)), "✅", "❌") -> ✅ | H20: 2021 | I20: =IF(COUNTIFS($E$2:$E$1000,H20,$F$2:$F$1000,">0")=0,"",AVERAGEIFS($F$2:$F$1000,$E$2:$E$1000,H20,$F$2:$F$1000,">0")) -> 2.64 | J20: =(I20-I19)/I19 -> 0
C21: 20 | D21: =EDATE(D20,1) -> 44044 | E21: =YEAR(D21) -> 2020 | F21: =INDEX(Fees!$B$2:$CG$99, MATCH(Calculator!$A$2,Fees!$A$2:$A$99,0), MATCH(Calculator!D21,Fees!$B$1:$CG$1,0)) -> 2.64 | G21: =IF(AND(F21>0, ISNUMBER(C21)), "✅", "❌") -> ✅ | H21: 2022 | I21: =IF(COUNTIFS($E$2:$E$1000,H21,$F$2:$F$1000,">0")=0,"",AVERAGEIFS($F$2:$F$1000,$E$2:$E$1000,H21,$F$2:$F$1000,">0")) | J21: =IFERROR((I21-I20)/I20,"N/A") -> N/A
C22: 21 | D22: =EDATE(D21,1) -> 44075 | E22: =YEAR(D22) -> 2020 | F22: =INDEX(Fees!$B$2:$CG$99, MATCH(Calculator!$A$2,Fees!$A$2:$A$99,0), MATCH(Calculator!D22,Fees!$B$1:$CG$1,0)) -> 2.64 | G22: =IF(AND(F22>0, ISNUMBER(C22)), "✅", "❌") -> ✅ | H22: 2023 | I22: =IF(COUNTIFS($E$2:$E$1000,H22,$F$2:$F$1000,">0")=0,"",AVERAGEIFS($F$2:$F$1000,$E$2:$E$1000,H22,$F$2:$F$1000,">0")) | J22: =IFERROR((I22-I21)/I21,"N/A") -> N/A
A23: Stable Regulatory Environment | B23: =AVERAGE(A10,A12,A14) -> 3.0679296 | C23: 22 | D23: =EDATE(D22,1) -> 44105 | E23: =YEAR(D23) -> 2020 | F23: =INDEX(Fees!$B$2:$CG$99, MATCH(Calculator!$A$2,Fees!$A$2:$A$99,0), MATCH(Calculator!D23,Fees!$B$1:$CG$1,0)) -> 2.64 | G23: =IF(AND(F23>0, ISNUMBER(C23)), "✅", "❌") -> ✅ | H23: 2024 | I23: =IF(COUNTIFS($E$2:$E$1000,H23,$F$2:$F$1000,">0")=0,"",AVERAGEIFS($F$2:$F$1000,$E$2:$E$1000,H23,$F$2:$F$1000,">0")) | J23: =IFERROR((I23-I22)/I22,"N/A") -> N/A
A24: Uncertainty or Change Expected | B24: =MAX(A10,A12,A14) -> 3.9658242 | C24: 23 | D24: =EDATE(D23,1) -> 44136 | E24: =YEAR(D24) -> 2020 | F24: =INDEX(Fees!$B$2:$CG$99, MATCH(Calculator!$A$2,Fees!$A$2:$A$99,0), MATCH(Calculator!D24,Fees!$B$1:$CG$1,0)) -> 2.64 | G24: =IF(AND(F24>0, ISNUMBER(C24)), "✅", "❌") -> ✅ | H24: 2025 | I24: =IF(COUNTIFS($E$2:$E$1000,H24,$F$2:$F$1000,">0")=0,"",AVERAGEIFS($F$2:$F$1000,$E$2:$E$1000,H24,$F$2:$F$1000,">0")) | J24: =IFERROR((I24-I23)/I23,"N/A") -> N/A
A25: Certain Regulatory Decision Expected w/h Manual Adjustment | B25: =A8 +(A8*A4) -> 0 | C25: 24 | D25: =EDATE(D24,1) -> 44166 | E25: =YEAR(D25) -> 2020 | F25: =INDEX(Fees!$B$2:$CG$99, MATCH(Calculator!$A$2,Fees!$A$2:$A$99,0), MATCH(Calculator!D25,Fees!$B$1:$CG$1,0)) -> 2.64 | G25: =IF(AND(F25>0, ISNUMBER(C25)), "✅", "❌") -> ✅ | I25: =AVERAGE(I18:I24) -> 2.5133333 | J25: =AVERAGE(J19:J24) -> 0.084070796
C26: 25 | D26: =EDATE(D25,1) -> 44197 | E26: =YEAR(D26) -> 2021 | F26: =INDEX(Fees!$B$2:$CG$99, MATCH(Calculator!$A$2,Fees!$A$2:$A$99,0), MATCH(Calculator!D26,Fees!$B$1:$CG$1,0)) -> 2.64 | G26: =IF(AND(F26>0, ISNUMBER(C26)), "✅", "❌") -> ✅
C27: 26 | D27: =EDATE(D26,1) -> 44228 | E27: =YEAR(D27) -> 2021 | F27: =INDEX(Fees!$B$2:$CG$99, MATCH(Calculator!$A$2,Fees!$A$2:$A$99,0), MATCH(Calculator!D27,Fees!$B$1:$CG$1,0)) -> 2.64 | G27: =IF(AND(F27>0, ISNUMBER(C27)), "✅", "❌") -> ✅ | H27: 3 yer Rolling Average
A28: ETS-Based Time Series Forecasting Model | C28: 27 | D28: =EDATE(D27,1) -> 44256 | E28: =YEAR(D28) -> 2021 | F28: =INDEX(Fees!$B$2:$CG$99, MATCH(Calculator!$A$2,Fees!$A$2:$A$99,0), MATCH(Calculator!D28,Fees!$B$1:$CG$1,0)) -> 2.64 | G28: =IF(AND(F28>0, ISNUMBER(C28)), "✅", "❌") -> ✅ | H28: Year | I28: Average | J28: MA(3)
C29: 28 | D29: =EDATE(D28,1) -> 44287 | E29: =YEAR(D29) -> 2021 | F29: =INDEX(Fees!$B$2:$CG$99, MATCH(Calculator!$A$2,Fees!$A$2:$A$99,0), MATCH(Calculator!D29,Fees!$B$1:$CG$1,0)) -> 0 | G29: =IF(AND(F29>0, ISNUMBER(C29)), "✅", "❌") -> ❌ | H29: 2019 | I29: =IF(COUNTIFS($E$2:$E$1000,H29,$F$2:$F$1000,">0")=0,"",AVERAGEIFS($F$2:$F$1000,$E$2:$E$1000,H29,$F$2:$F$1000,">0")) -> 2.26
C30: 29 | D30: =EDATE(D29,1) -> 44317 | E30: =YEAR(D30) -> 2021 | F30: =INDEX(Fees!$B$2:$CG$99, MATCH(Calculator!$A$2,Fees!$A$2:$A$99,0), MATCH(Calculator!D30,Fees!$B$1:$CG$1,0)) -> 0 | G30: =IF(AND(F30>0, ISNUMBER(C30)), "✅", "❌") -> ❌ | H30: 2020 | I30: =IF(COUNTIFS($E$2:$E$1000,H30,$F$2:$F$1000,">0")=0,"",AVERAGEIFS($F$2:$F$1000,$E$2:$E$1000,H30,$F$2:$F$1000,">0")) -> 2.64
C31: 30 | D31: =EDATE(D30,1) -> 44348 | E31: =YEAR(D31) -> 2021 | F31: =INDEX(Fees!$B$2:$CG$99, MATCH(Calculator!$A$2,Fees!$A$2:$A$99,0), MATCH(Calculator!D31,Fees!$B$1:$CG$1,0)) -> 0 | G31: =IF(AND(F31>0, ISNUMBER(C31)), "✅", "❌") -> ❌ | H31: 2021 | I31: =IF(COUNTIFS($E$2:$E$1000,H31,$F$2:$F$1000,">0")=0,"",AVERAGEIFS($F$2:$F$1000,$E$2:$E$1000,H31,$F$2:$F$1000,">0")) -> 2.64 | J31: =IF(COUNT(I29:I31)>2, AVERAGE(I29:I31),0) -> 2.5133333
C32: 31 | D32: =EDATE(D31,1) -> 44378 | E32: =YEAR(D32) -> 2021 | F32: =INDEX(Fees!$B$2:$CG$99, MATCH(Calculator!$A$2,Fees!$A$2:$A$99,0), MATCH(Calculator!D32,Fees!$B$1:$CG$1,0)) -> 0 | G32: =IF(AND(F32>0, ISNUMBER(C32)), "✅", "❌") -> ❌ | H32: 2022 | I32: =IF(COUNTIFS($E$2:$E$1000,H32,$F$2:$F$1000,">0")=0,"",AVERAGEIFS($F$2:$F$1000,$E$2:$E$1000,H32,$F$2:$F$1000,">0")) | J32: =IF(COUNT(I30:I32)>2, AVERAGE(I30:I32),0) -> 0
C33: 32 | D33: =EDATE(D32,1) -> 44409 | E33: =YEAR(D33) -> 2021 | F33: =INDEX(Fees!$B$2:$CG$99, MATCH(Calculator!$A$2,Fees!$A$2:$A$99,0), MATCH(Calculator!D33,Fees!$B$1:$CG$1,0)) -> 0 | G33: =IF(AND(F33>0, ISNUMBER(C33)), "✅", "❌") -> ❌ | H33: 2023 | I33: =IF(COUNTIFS($E$2:$E$1000,H33,$F$2:$F$1000,">0")=0,"",AVERAGEIFS($F$2:$F$1000,$E$2:$E$1000,H33,$F$2:$F$1000,">0")) | J33: =IF(COUNT(I31:I33)>2, AVERAGE(I31:I33),0) -> 0
C34: 33 | D34: =EDATE(D33,1) -> 44440 | E34: =YEAR(D34) -> 2021 | F34: =INDEX(Fees!$B$2:$CG$99, MATCH(Calculator!$A$2,Fees!$A$2:$A$99,0), MATCH(Calculator!D34,Fees!$B$1:$CG$1,0)) -> 0 | G34: =IF(AND(F34>0, ISNUMBER(C34)), "✅", "❌") -> ❌ | H34: 2024 | I34: =IF(COUNTIFS($E$2:$E$1000,H34,$F$2:$F$1000,">0")=0,"",AVERAGEIFS($F$2:$F$1000,$E$2:$E$1000,H34,$F$2:$F$1000,">0")) | J34: =IF(COUNT(I32:I34)>2, AVERAGE(I32:I34),0) -> 0
C35: 34 | D35: =EDATE(D34,1) -> 44470 | E35: =YEAR(D35) -> 2021 | F35: =INDEX(Fees!$B$2:$CG$99, MATCH(Calculator!$A$2,Fees!$A$2:$A$99,0), MATCH(Calculator!D35,Fees!$B$1:$CG$1,0)) -> 0 | G35: =IF(AND(F35>0, ISNUMBER(C35)), "✅", "❌") -> ❌ | H35: 2025 | I35: =IF(COUNTIFS($E$2:$E$1000,H35,$F$2:$F$1000,">0")=0,"",AVERAGEIFS($F$2:$F$1000,$E$2:$E$1000,H35,$F$2:$F$1000,">0")) | J35: =IF(COUNT(I33:I35)>2, AVERAGE(I33:I35),0) -> 0
C36: 35 | D36: =EDATE(D35,1) -> 44501 | E36: =YEAR(D36) -> 2021 | F36: =INDEX(Fees!$B$2:$CG$99, MATCH(Calculator!$A$2,Fees!$A$2:$A$99,0), MATCH(Calculator!D36,Fees!$B$1:$CG$1,0)) -> 0 | G36: =IF(AND(F36>0, ISNUMBER(C36)), "✅", "❌") -> ❌
C37: 36 | D37: =EDATE(D36,1) -> 44531 | E37: =YEAR(D37) -> 2021 | F37: =INDEX(Fees!$B$2:$CG$99, MATCH(Calculator!$A$2,Fees!$A$2:$A$99,0), MATCH(Calculator!D37,Fees!$B$1:$CG$1,0)) -> 0 | G37: =IF(AND(F37>0, ISNUMBER(C37)), "✅", "❌") -> ❌
C38: 37 | D38: 44562 | E38: =YEAR(D38) -> 2022 | F38: =INDEX(Fees!$B$2:$CG$99, MATCH(Calculator!$A$2,Fees!$A$2:$A$99,0), MATCH(Calculator!D38,Fees!$B$1:$CG$1,0)) -> 0 | G38: =IF(AND(F38>0, ISNUMBER(C38)), "✅", "❌") -> ❌
C39: 38 | D39: 44593 | E39: =YEAR(D39) -> 2022 | F39: =INDEX(Fees!$B$2:$CG$99, MATCH(Calculator!$A$2,Fees!$A$2:$A$99,0), MATCH(Calculator!D39,Fees!$B$1:$CG$1,0)) -> 0 | G39: =IF(AND(F39>0, ISNUMBER(C39)), "✅", "❌") -> ❌
C40: 39 | D40: 44621 | E40: =YEAR(D40) -> 2022 | F40: =INDEX(Fees!$B$2:$CG$99, MATCH(Calculator!$A$2,Fees!$A$2:$A$99,0), MATCH(Calculator!D40,Fees!$B$1:$CG$1,0)) -> 0 | G40: =IF(AND(F40>0, ISNUMBER(C40)), "✅", "❌") -> ❌
...

Sheet Validation
D6: Fees | E6: Actual 2025 fee | F6: ETS Forecasted for 2025 | G6: Diff % | H6: Average YOY fee | I6: Diff % | J6: Weighted 3-year Average | K6: Diff % | L6: Average of Previous Year | M6: Diff %
D7: Distribution fixed fee NAF_Distribution fixed fee_NAF | E7: 433008 | F7: 463238.7 | G7: =(F7-E7)/F7 -> 0.06525945 | H7: 345466.28 | I7: =(H7-E7)/H7 -> -0.25340165 | J7: 293226.5 | K7: =(J7-E7)/J7 -> -0.47670146 | L7: 433176 | M7: =(L7-E7)/L7 -> 0.00038783312
D8: KÁT and Premium financial instrument NAF_KÁT and Premium financial instrument_NAF | E8: 0.75833333 | F8: 0.50386972 | G8: =(F8-E8)/F8 -> -0.50501867 | H8: 3.0750149 | I8: =(H8-E8)/H8 -> 0.75338873 | J8: 2.4095215 | K8: =(J8-E8)/J8 -> 0.68527638 | L8: 5.4329444 | M8: =(L8-E8)/L8 -> 0.86041946
D9: Distribution fixed fee MV_Distribution fixed fee_MV | E9: 216504 | F9: 231619.35 | G9: =(F9-E9)/F9 -> 0.06525945 | H9: 172733.14 | I9: =(H9-E9)/H9 -> -0.25340165 | J9: 146613.25 | K9: =(J9-E9)/J9 -> -0.47670146 | L9: 216588 | M9: =(L9-E9)/L9 -> 0.00038783312
D10: Distribution fixed fee MV/LV1_Distribution fixed fee_MV/LV1 | E10: 7212 | F10: 7725.2601 | G10: =(F10-E10)/F10 -> 0.066439204 | H10: 5760.6461 | I10: =(H10-E10)/H10 -> -0.2519429 | J10: 4889 | K10: =(J10-E10)/J10 -> -0.47514829 | L10: 7224 | M10: =(L10-E10)/L10 -> 0.0016611296
D11: Distribution fixed fee MV/LV3_Distribution fixed fee_MV/LV3 | E11: 72168 | F11: 77201.406 | G11: =(F11-E11)/F11 -> 0.065198371 | H11: 57576.526 | I11: =(H11-E11)/H11 -> -0.25342749 | J11: 48872 | K11: =(J11-E11)/J11 -> -0.47667376 | L11: 72192 | M11: =(L11-E11)/L11 -> 0.00033244681
D12: Distribution capacity fee NAF_Distribution capacity fee_NAF | E12: 2376 | F12: 2533.0459 | G12: =(F12-E12)/F12 -> 0.061998844 | H12: 2374.8868 | I12: =(H12-E12)/H12 -> -0.00046872277 | J12: 1962 | K12: =(J12-E12)/J12 -> -0.21100917 | L12: 2376 | M12: =(L12-E12)/L12 -> 0
D13: Distribution capacity fee NAF/MV_Distribution capacity fee_NAF/MV | E13: 8004 | F13: 8941.1165 | G13: =(F13-E13)/F13 -> 0.10480978 | H13: 7381.9493 | I13: =(H13-E13)/H13 -> -0.084266449 | J13: 6624.75 | K13: =(J13-E13)/J13 -> -0.20819654 | L13: 8004 | M13: =(L13-E13)/L13 -> 0
D14: Distribution capacity fee MV_Distribution capacity fee_MV | E14: 15924 | F14: 16711.223 | G14: =(F14-E14)/F14 -> 0.047107426 | H14: 13273.077 | I14: =(H14-E14)/H14 -> -0.19972181 | J14: 11576.25 | K14: =(J14-E14)/J14 -> -0.37557499 | L14: 15924 | M14: =(L14-E14)/L14 -> 0
D15: Distribution capacity fee LV3_Distribution capacity fee_LV3 | E15: 13248 | F15: 13689.173 | G15: =(F15-E15)/F15 -> 0.032227844 | H15: 11195.438 | I15: =(H15-E15)/H15 -> -0.18333916 | J15: 9947.25 | K15: =(J15-E15)/J15 -> -0.33182538 | L15: 13248 | M15: =(L15-E15)/L15 -> 0
D16: Distribution usage fee NAF_Distribution usage fee_NAF | E16: 2.87 | F16: 1.4151242 | G16: =(F16-E16)/F16 -> -1.0280905 | H16: 3.9747297 | I16: =(H16-E16)/H16 -> 0.27793832 | J16: 1.069375 | K16: =(J16-E16)/J16 -> -1.6838106 | L16: 1.12 | M16: =(L16-E16)/L16 -> -1.5625
D17: Distribution usage fee NAF/MV_Distribution usage fee_NAF/MV | E17: 4.3 | F17: 3.0941038 | G17: =(F17-E17)/F17 -> -0.38974006 | H17: 6.6184004 | I17: =(H17-E17)/H17 -> 0.35029618 | J17: 2.1475 | K17: =(J17-E17)/J17 -> -1.0023283 | L17: 2.55 | M17: =(L17-E17)/L17 -> -0.68627451
D18: Distribution usage fee MV_Distribution usage fee_MV | E18: 9.27 | F18: 8.4670931 | G18: =(F18-E18)/F18 -> -0.094826742 | H18: 7.1938366 | I18: =(H18-E18)/H18 -> -0.28860308 | J18: 3.775625 | K18: =(J18-E18)/J18 -> -1.4552226 | L18: 7.52 | M18: =(L18-E18)/L18 -> -0.23271277
... D23: Distribution usage fee LV3_Distribution usage fee_LV3 | E23: 23.08 | F23: 23.723622 | G23: =(F23-E23)/F23 -> 0.027130013 | H23: 17.27303 | I23: =(H23-E23)/H23 -> -0.33618708 | J23: 9.9422917 | K23: =(J23-E23)/J23 -> -1.3213964 | L23: 21.33 | M23: =(L23-E23)/L23 -> -0.082044069
E24: Average Diff% | G24: =AVERAGE(G7:G23) -> -0.099114318 | I24: =AVERAGE(I7:I23) -> -0.12865921 | K24: =AVERAGE(K7:K23) -> -0.67289892 | M24: =AVERAGE(M7:M23) -> -0.13111072
